Workbook

Sheet 📋 Cover
A1: ALPHAEDGE — GLOBAL EMERGING MARKETS INTELLIGENCE
A2: Business Logic & Parameter Reference Export | February 2026
A4: PURPOSE
A5: This workbook exports all business logic, market parameters, correlation coefficients,
A6: risk scores, macro drivers, crisis prediction signals, and lead-lag relationships
A7: from the AlphaEdge Global Correlation Engine platform.
A9: SHEETS IN THIS WORKBOOK
A10: 01 — Market Parameters — All 45 EM markets: index, FX, macro, tier, mktcap
A11: 02 — Correlation Matrix — 5 correlation coefficients per market (SPX, Oil, USD, Gold, China)
A12: 03 — Risk & Macro Scores — Risk score, GDP, CPI, rates, current account, debt/GDP
A13: 04 — Crisis Predictor — 5-signal early-warning system weights, thresholds, accuracy
A14: 05 — Lead-Lag Engine — Research-backed lead-lag relationships with lag days & strength
... A31: CLASSIFICATION: Internal Use — Share with development and product teams

Sheet 01 — Market Parameters
A1: ALPHAEDGE — MARKET PARAMETERS (45 EMERGING MARKETS)
A2: Region | B2: ID | C2: Country | D2: Flag | E2: Index | F2: Index Value | G2: Currency | H2: FX Rate (per USD) | I2: FX 1D Change % | J2: Market Tier | K2: Market Cap
A3: South Asia | B3: IN | C3: 🇮🇳 India | D3: 🇮🇳 | E3: NIFTY 50 | F3: 21345 | G3: INR | H3: 83.42 | I3: -0.0021 | J3: Frontier-Plus | K3: $3.9T
A4: South Asia | B4: PK | C4: 🇵🇰 Pakistan | D4: 🇵🇰 | E4: KSE-100 | F4: 62410 | G4: PKR | H4: 278.5 | I4: -0.0082 | J4: Frontier | K4: $52B
A5: South Asia | B5: BD | C5: 🇧🇩 Bangladesh | D5: 🇧🇩 | E5: DSEX | F5: 6245 | G5: BDT | H5: 110.2 | I5: -0.0015 | J5: Frontier | K5: $48B
A6: South Asia | B6: LK | C6: 🇱🇰 Sri Lanka | D6: 🇱🇰 | E6: CSE All | F6: 8912 | G6: LKR | H6: 318.4 | I6: 0.0034 | J6: Frontier | K6: $7B
A7: Southeast Asia | B7: ID | C7: 🇮🇩 Indonesia | D7: 🇮🇩 | E7: IDX Comp | F7: 7282 | G7: IDR | H7: 15820 | I7: -0.0012 | J7: Emerging | K7: $678B
A8: Southeast Asia | B8: MY | C8: 🇲🇾 Malaysia | D8: 🇲🇾 | E8: KLCI | F8: 1524 | G8: MYR | H8: 4.74 | I8: -0.0018 | J8: Emerging | K8: $384B
A9: Southeast Asia | B9: TH | C9: 🇹🇭 Thailand | D9: 🇹🇭 | E9: SET | F9: 1415 | G9: THB | H9: 35.2 | I9: -0.0009 | J9: Emerging | K9: $488B
A10: Southeast Asia | B10: PH | C10: 🇵🇭 Philippines | D10: 🇵🇭 | E10: PSEi | F10: 6892 | G10: PHP | H10: 57.8 | I10: -0.0022 | J10: Emerging | K10: $218B
A11: Southeast Asia | B11: VN | C11: 🇻🇳 Vietnam | D11: 🇻🇳 | E11: VN-Index | F11: 1248 | G11: VND | H11: 25420 | I11: -0.0008 | J11: Frontier-Plus | K11: $182B
A12: Southeast Asia | B12: SG | C12: 🇸🇬 Singapore | D12: 🇸🇬 | E12: STI | F12: 3248 | G12: SGD | H12: 1.345 | I12: -0.0014 | J12: Developed-EM | K12: $421B
A13: East Asia | B13: CN | C13: 🇨🇳 China | D13: 🇨🇳 | E13: CSI 300 | F13: 3412 | G13: CNY | H13: 7.234 | I13: 0.0004 | J13: Emerging | K13: $9.4T
A14: East Asia | B14: KR | C14: 🇰🇷 South Korea | D14: 🇰🇷 | E14: KOSPI | F14: 2584 | G14: KRW | H14: 1328 | I14: -0.0018 | J14: Emerging | K14: $1.6T
... A40: Emerging Europe | B40: GR | C40: 🇬🇷 Greece | D40: 🇬🇷 | E40: Athens GE | F40: 1484 | G40: EUR | H40: 1.085 | I40: -0.0008 | J40: Developed-EM | K40: $52B

Sheet 02 — Correlation Matrix
A1: ALPHAEDGE — GLOBAL CORRELATION COEFFICIENTS (30-Day Rolling DCC-GARCH)
A2: Region | B2: ID | C2: Country | D2: vs S&P 500 | E2: vs Brent Oil | F2: vs USD Index | G2: vs Gold | H2: vs China PMI | I2: SPX Regime | J2: Oil Regime | K2: USD Regime
A3: South Asia | B3: IN | C3: 🇮🇳 India | D3: 0.68 | E3: -0.42 | F3: -0.58 | G3: -0.22 | H3: 0.45 | I3: Moderate Positive | J3: Strong Negative | K3: Strong Negative
A4: South Asia | B4: PK | C4: 🇵🇰 Pakistan | D4: 0.28 | E4: -0.55 | F4: -0.71 | G4: 0.21 | H4: 0.38 | I4: Weak Positive | J4: Strong Negative | K4: Strong Negative
A5: South Asia | B5: BD | C5: 🇧🇩 Bangladesh | D5: 0.31 | E5: -0.38 | F5: -0.48 | G5: 0.12 | H5: 0.42 | I5: Weak Positive | J5: Weak Negative | K5: Strong Negative
A6: South Asia | B6: LK | C6: 🇱🇰 Sri Lanka | D6: 0.22 | E6: -0.48 | F6: -0.61 | G6: 0.18 | H6: 0.29 | I6: Weak Positive | J6: Strong Negative | K6: Strong Negative
A7: Southeast Asia | B7: ID | C7: 🇮🇩 Indonesia | D7: 0.55 | E7: 0.42 | F7: -0.52 | G7: 0.18 | H7: 0.58 | I7: Moderate Positive | J7: Moderate Positive | K7: Strong Negative
A8: Southeast Asia | B8: MY | C8: 🇲🇾 Malaysia | D8: 0.58 | E8: 0.35 | F8: -0.61 | G8: 0.14 | H8: 0.62 | I8: Moderate Positive | J8: Weak Positive | K8: Strong Negative
A9: Southeast Asia | B9: TH | C9: 🇹🇭 Thailand | D9: 0.52 | E9: -0.28 | F9: -0.55 | G9: 0.08 | H9: 0.55 | I9: Moderate Positive | J9: Weak Negative | K9: Strong Negative
A10: Southeast Asia | B10: PH | C10: 🇵🇭 Philippines | D10: 0.51 | E10: -0.31 | F10: -0.62 | G10: 0.11 | H10: 0.44 | I10: Moderate Positive | J10: Weak Negative | K10: Strong Negative
A11: Southeast Asia | B11: VN | C11: 🇻🇳 Vietnam | D11: 0.44 | E11: -0.18 | F11: -0.51 | G11: 0.22 | H11: 0.52 | I11: Moderate Positive | J11: Weak Negative | K11: Strong Negative
A12: Southeast Asia | B12: SG | C12: 🇸🇬 Singapore | D12: 0.61 | E12: 0.38 | F12: -0.52 | G12: 0.18 | H12: 0.58 | I12: Moderate Positive | J12: Weak Positive | K12: Strong Negative
A13: East Asia | B13: CN | C13: 🇨🇳 China | D13: 0.54 | E13: 0.12 | F13: -0.41 | G13: 0.05 | H13: 1 | I13: Moderate Positive | J13: Weak Positive | K13: Strong Negative
A14: East Asia | B14: KR | C14: 🇰🇷 South Korea | D14: 0.72 | E14: -0.22 | F14: -0.68 | G14: -0.12 | H14: 0.62 | I14: Strong Positive | J14: Weak Negative | K14: Strong Negative
... A40: Emerging Europe | B40: GR | C40: 🇬🇷 Greece | D40: 0.61 | E40: -0.22 | F40: -0.78 | G40: 0.18 | H40: 0.28 | I40: Moderate Positive | J40: Weak Negative | K40: Strong Negative

Sheet 03 — Risk & Macro Scores
A1: ALPHAEDGE — RISK SCORES & MACRO INDICATORS
A2: Region | B2: ID | C2: Country | D2: Risk Score (0-100) | E2: Risk Level | F2: GDP Growth % | G2: Inflation (CPI) % | H2: Interest Rate % | I2: Bond Yield (10Y) % | J2: Current Account % GDP | K2: Debt / GDP % | L2: Real Rate (Rate - CPI)
A3: South Asia | B3: IN | C3: 🇮🇳 India | D3: 38 | E3: MEDIUM | F3: 0.068 | G3: 0.048 | H3: 0.065 | I3: 0.071 | J3: -0.012 | K3: 0.83 | L3: =H3-G3 -> 0.017
A4: South Asia | B4: PK | C4: 🇵🇰 Pakistan | D4: 78 | E4: CRITICAL | F4: 0.018 | G4: 0.224 | H4: 0.22 | I4: 0.225 | J4: -0.038 | K4: 0.77 | L4: =H4-G4 -> -0.004
A5: South Asia | B5: BD | C5: 🇧🇩 Bangladesh | D5: 52 | E5: MEDIUM | F5: 0.055 | G5: 0.092 | H5: 0.0875 | I5: 0.092 | J5: -0.014 | K5: 0.38 | L5: =H5-G5 -> -0.0045
A6: South Asia | B6: LK | C6: 🇱🇰 Sri Lanka | D6: 72 | E6: CRITICAL | F6: 0.028 | G6: 0.121 | H6: 0.09 | I6: 0.108 | J6: -0.032 | K6: 1.15 | L6: =H6-G6 -> -0.031
A7: Southeast Asia | B7: ID | C7: 🇮🇩 Indonesia | D7: 42 | E7: MEDIUM | F7: 0.05 | G7: 0.028 | H7: 0.06 | I7: 0.0685 | J7: -0.004 | K7: 0.39 | L7: =H7-G7 -> 0.032
A8: Southeast Asia | B8: MY | C8: 🇲🇾 Malaysia | D8: 36 | E8: MEDIUM | F8: 0.044 | G8: 0.018 | H8: 0.03 | I8: 0.0395 | J8: 0.018 | K8: 0.66 | L8: =H8-G8 -> 0.012
A9: Southeast Asia | B9: TH | C9: 🇹🇭 Thailand | D9: 44 | E9: MEDIUM | F9: 0.025 | G9: 0.008 | H9: 0.025 | I9: 0.0295 | J9: 0.012 | K9: 0.61 | L9: =H9-G9 -> 0.017
A10: Southeast Asia | B10: PH | C10: 🇵🇭 Philippines | D10: 46 | E10: MEDIUM | F10: 0.056 | G10: 0.032 | H10: 0.065 | I10: 0.0675 | J10: -0.034 | K10: 0.57 | L10: =H10-G10 -> 0.033
A11: Southeast Asia | B11: VN | C11: 🇻🇳 Vietnam | D11: 39 | E11: MEDIUM | F11: 0.062 | G11: 0.034 | H11: 0.045 | I11: 0.0485 | J11: 0.028 | K11: 0.37 | L11: =H11-G11 -> 0.011
A12: Southeast Asia | B12: SG | C12: 🇸🇬 Singapore | D12: 18 | E12: LOW | F12: 0.011 | G12: 0.032 | H12: 0.0386 | I12: 0.0328 | J12: 0.17 | K12: 1.68 | L12: =H12-G12 -> 0.0066
A13: East Asia | B13: CN | C13: 🇨🇳 China | D13: 55 | E13: HIGH | F13: 0.048 | G13: 0.002 | H13: 0.0345 | I13: 0.0258 | J13: 0.018 | K13: 2.88 | L13: =H13-G13 -> 0.0325
A14: East Asia | B14: KR | C14: 🇰🇷 South Korea | D14: 28 | E14: LOW | F14: 0.025 | G14: 0.026 | H14: 0.035 | I14: 0.0362 | J14: 0.014 | K14: 0.54 | L14: =H14-G14 -> 0.009
... A40: Emerging Europe | B40: GR | C40: 🇬🇷 Greece | D40: 44 | E40: MEDIUM | F40: 0.021 | G40: 0.032 | H40: 0.045 | I40: 0.0358 | J40: -0.078 | K40: 1.61 | L40: =H40-G40 -> 0.013

Sheet 04 — Crisis Predictor
A1: CRISIS CORRELATION PREDICTOR™ — 5-SIGNAL EARLY WARNING SYSTEM
A2: Patent Pending · Historical Accuracy: 73% · False Positive Rate: 27% · Average Lead Time: 5.2 days
A4: Signal Name | B4: Weight | C4: Threshold | D4: Lead Time (Days) | E4: Historical Accuracy | F4: Trigger Logic | G4: Current Status | H4: Contribution to Risk
A5: VIX Acceleration | B5: 0.4 | C5: 3-day change > 15% | D5: 5 | E5: 0.82 | F5: If 3D_VIX_change > 0.15 → TRIGGERED | G5: ACTIVE | H5: 0.4
A6: Treasury Volatility | B6: 0.25 | C6: 10Y move > 8bps/day | D6: 2 | E6: 0.76 | F6: If rolling_10Y_vol > 0.08 → TRIGGERED | G6: ACTIVE | H6: 0.25
A7: FX Stress Index | B7: 0.2 | C7: EM FX Z-score > 2.5 | D7: 3 | E7: 0.71 | F7: If abs(EM_FX_zscore) > 2.5 → TRIGGERED | G7: INACTIVE | H7: 0
A8: Credit Spread Widening | B8: 0.1 | C8: IG spreads > 15% 3M avg | D8: 7 | E8: 0.68 | F8: If IG_spread / IG_3M_avg > 1.15 → TRIGGERED | G8: INACTIVE | H8: 0
A9: Commodity Dislocation | B9: 0.05 | C9: |corr(Oil,Gold)| < 0.1 | D9: 4 | E9: 0.64 | F9: If abs(oil_gold_corr) < 0.1 → TRIGGERED | G9: ACTIVE | H9: 0.05
A11: CURRENT CRISIS PROBABILITY (Weighted Sum) | B11: =SUMPRODUCT(B5:B9,H5:H9) -> 0.225 | C11: → If > 60%: ELEVATED | If > 70%: CRITICAL
A13: REGIME CLASSIFICATION THRESHOLDS
A14: Probability Range | B14: Regime | C14: Action Required | D14: Expected Correlation Spike | E14: Drawdown Risk Premium
A15: 0% – 40% | B15: NORMAL | C15: Maintain allocation | D15: 0.65 – 0.70 (baseline) | E15: 0%
A16: 40% – 60% | B16: WATCH | C16: Monitor closely, review hedges | D16: 0.70 – 0.78 | E16: 5% – 8%
A17: 60% – 70% | B17: ELEVATED | C17: Reduce equity 10%, add Gold | D17: 0.78 – 0.85 | E17: 8% – 15%
A18: 70% – 85% | B18: CRITICAL | C18: Reduce equity 15-20%, buy puts | D18: 0.85 – 0.92 | E18: 15% – 25%
A19: > 85% | B19: CRISIS | C19: Defensive posture | D19: 0.90 – 0.95+ | E19: 25% – 40%

Sheet 05 — Lead-Lag Engine
A1: LEAD-LAG RELATIONSHIP ENGINE — Research-Backed Granger Causality
A2: Leading Indicator | B2: Lagging Indicator | C2: Lag (Days) | D2: Granger P-Value | E2: Strength (0-1) | F2: Confidence | G2: Category | H2: Research Source | I2: Trading Implication
A3: US 10Y Treasury Yield | B3: India 10Y Bond Yield | C3: 2 | D3: 0.001 | E3: 0.85 | F3: HIGH | G3: Rates | H3: Bi-dir Granger 2023 | I3: When US 10Y rises, India 10Y follows in 2 days
A4: S&P 500 | B4: Nifty 50 | C4: 1 | D4: 0.003 | E4: 0.82 | F4: HIGH | G4: Equity | H4: SEBI Research 2024 | I4: US equity down → India opens down next day
A5: VIX Index | B5: EM Selloff | C5: 5 | D5: 0.001 | E5: 0.89 | F5: HIGH | G5: Volatility | H5: IMF Working Paper | I5: VIX spike > 25 = EM selloff within 5 days
A6: Oil Price (Brent) | B6: India CPI | C6: 30 | D6: 0.004 | E6: 0.78 | F6: HIGH | G6: Inflation | H6: RBI Working Paper | I6: Oil +10% = India CPI +1.5% in 30 days
A7: DXY Index | B7: INR/USD Rate | C7: 0 | D7: 0.001 | E7: 0.91 | F7: HIGH | G7: FX | H7: Bloomberg Research | I7: Same-day: DXY +1% = INR -0.4 to -0.6%
A8: China PMI | B8: European Exporters | C8: 15 | D8: 0.006 | E8: 0.72 | F8: MEDIUM | G8: Macro | H8: ECB Research 2024 | I8: China PMI < 50 = EU industrial stocks -2%
A9: China PMI | B9: Iron Ore Price | C9: 1 | D9: 0.002 | E9: 0.88 | F9: HIGH | G9: Commodity | H9: BHP Research | I9: China PMI misses = Iron Ore -2.5% per point
A10: China Credit Impulse | B10: Global Growth (6M lag) | C10: 180 | D10: 0.008 | E10: 0.74 | F10: MEDIUM | G10: Macro | H10: CrossBorder Capital | I10: China credit expansion predicts global GDP
A11: US Corporate Spreads | B11: EM Bond Spreads | C11: 7 | D11: 0.003 | E11: 0.81 | F11: HIGH | G11: Credit | H11: JPM EM Research | I11: IG spreads widen > 15% = EM spreads follow
A12: Singapore NODX | B12: ASEAN Trade | C12: 3 | D12: 0.011 | E12: 0.68 | F12: MEDIUM | G12: Trade | H12: MAS Research | I12: Singapore trade data is ASEAN leading indicator
A13: US Fed Funds Futures | B13: EM FX | C13: 2 | D13: 0.002 | E13: 0.83 | F13: HIGH | G13: Rates/FX | H13: Goldman FX Research | I13: Fed hawkish shift → EM FX selling in 2 days
A14: Nasdaq 100 | B14: Indian IT Sector | C14: 1 | D14: 0.004 | E14: 0.81 | F14: HIGH | G14: Equity | H14: NSE Research | I14: Nasdaq -1% = Indian IT -0.7% to -0.9% next day
... A17: Africa Commodity Index | B17: China Infrastructure PMI | C17: 5 | D17: 0.014 | E17: 0.65 | F17: MEDIUM | G17: Commodity | H17: AfDB Research | I17: China infra slowdown hits Africa commodity exports

Sheet 06 — Transmission Models
A1: MACRO TRANSMISSION MODELS — US→India · Oil→India · China→India
A3: MODEL 1: US FED RATE HIKE → INDIA TRANSMISSION
A4: Parameter | B4: Value | C4: Unit | D4: Confidence | E4: Timeline | F4: Affected Sector | G4: Direction
A5: Input: Fed Rate Hike (bps) | B5: 50 | C5: bps | D5: Input | E5: T+0 | F5: All | G5: N/A
A6: DXY Strengthening | B6: =B5*0.008 -> 0.4 | C6: % / 50bps | D6: HIGH | E6: T+0 | F6: USD Index | G6: Positive
A7: FII Outflow (per 50bps) | B7: 400 | C7: Rs Crore | D7: HIGH | E7: T+1-2d | F7: All Equities | G7: Negative
A8: Nifty Impact (per Rs 1000Cr outflow) | B8: -0.15 | C8: % per 1KCr | D8: HIGH | E8: T+2-5d | F8: Nifty 50 | G8: Negative
A9: INR Depreciation | B9: =B6*0.15 -> 0.06 | C9: % per 1% DXY | D9: MEDIUM | E9: T+0-7d | F9: INR/USD | G9: Negative
A10: IT Sector Benefit (USD revenue) | B10: =B6*0.5 -> 0.2 | C10: % per 1% DXY | D10: HIGH | E10: T+1-2d | F10: IT Stocks | G10: Positive
A11: Banking Sector Impact | B11: -1.2 | C11: % typical | D11: HIGH | E11: T+2-3d | F11: Banks | G11: Negative
A12: Auto Sector Impact | B12: -0.8 | C12: % typical | D12: MEDIUM | E12: T+2-5d | F12: Auto Stocks | G12: Negative
A13: Pharma Benefit (USD exports) | B13: =B6*0.3 -> 0.12 | C13: % per 1% DXY | D13: MEDIUM | E13: T+2-3d | F13: Pharma | G13: Positive
A14: OMC Impact | B14: -0.3 | C14: % typical | D14: MEDIUM | E14: T+2-5d | F14: Oil Marketers | G14: Negative
A15: Model Accuracy (Historical) | B15: 0.76 | C15: confidence | D15: HIGH | E15: Backtest | F15: Full Model | G15: N/A
A18: MODEL 2: OIL PRICE CHANGE → INDIA IMPACT
A19: Parameter | B19: Value | C19: Unit | D19: Confidence | E19: Timeline | F19: Affected Sector | G19: Direction
A20: Input: Brent Oil Change (%) | B20: 10 | C20: % | D20: Input | E20: T+0 | F20: All | G20: N/A
A21: INR Depreciation (per 10% oil rise) | B21: -4 | C21: % | D21: HIGH | E21: T+0-7d | F21: INR/USD | G21: Negative
A22: OMC (IOC/BPCL/HPCL) Impact | B22: -1.2 | C22: % per 1% oil | D22: HIGH | E22: T+0 | F22: Oil Marketers | G22: Negative
A23: Airlines Impact | B23: -0.8 | C23: % per 1% oil | D23: HIGH | E23: T+0 | F23: IndiGo/SpiceJet | G23: Negative
A24: Logistics Impact | B24: -0.5 | C24: % per 1% oil | D24: MEDIUM | E24: T+0 | F24: Blue Dart/VRL | G24: Negative
A25: Paint Companies Impact | B25: -0.3 | C25: % per 1% oil | D25: MEDIUM | E25: T+5-10d | F25: Asian Paints | G25: Negative
A26: India CPI Increase (per 10% oil) | B26: 1.5 | C26: bps | D26: HIGH | E26: T+30d | F26: CPI Index | G26: Negative
A27: RBI Hawkish Probability (oil>$90) | B27: 0.65 | C27: probability | D27: MEDIUM | E27: T+30-60d | F27: RBI Policy | G27: Negative
A28: IT Exporter Benefit (USD strength) | B28: =B20*0.5 -> 5 | C28: % per 1% INR | D28: HIGH | E28: T+1-2d | F28: IT Stocks | G28: Positive
A29: Pharma Exporter Benefit | B29: =B20*0.3 -> 3 | C29: % per 1% INR | D29: MEDIUM | E29: T+1-2d | F29: Pharma | G29: Positive
A30: Current Account Deficit Widening | B30: -0.4 | C30: % GDP per 10% oil | D30: HIGH | E30: T+30-60d | F30: CAD | G30: Negative
A31: Model Accuracy (Historical) | B31: 0.74 | C31: confidence | D31: HIGH | E31: Backtest | F31: Full Model | G31: N/A
A34: MODEL 3: CHINA PMI MISS → COMMODITY & INDIA IMPACT
A35: Parameter | B35: Value | C35: Unit | D35: Confidence | E35: Timeline | F35: Affected Sector | G35: Direction
A36: Input: China PMI Miss (points below 50) | B36: 2 | C36: points | D36: Input | E36: T+0 | F36: China PMI | G36: N/A
A37: Iron Ore Price Impact | B37: -5 | C37: % per point | D37: HIGH | E37: T+0-1d | F37: Iron Ore | G37: Negative
A38: Copper Price Impact | B38: -3.6 | C38: % per point | D38: HIGH | E38: T+0-1d | F38: LME Copper | G38: Negative
A39: Coal Price Impact | B39: -4 | C39: % per point | D39: HIGH | E39: T+0-2d | F39: Coal | G39: Negative
A40: Tata Steel / JSW Impact | B40: -1.5 | C40: % per point | D40: HIGH | E40: T+1-5d | F40: Indian Metals | G40: Negative
A41: Hindalco Impact | B41: -1 | C41: % per point | D41: MEDIUM | E41: T+1-5d | F41: Aluminium | G41: Negative
A42: Cement (UltraTech) Impact | B42: -0.8 | C42: % per point | D42: MEDIUM | E42: T+3-10d | F42: Cement | G42: Negative
A43: Indian Infra / L&T Impact | B43: -0.6 | C43: % per point | D43: MEDIUM | E43: T+3-10d | F43: Infrastructure | G43: Negative
A44: Australia / BHP Benefit / Loss | B44: -2 | C44: % per point | D44: HIGH | E44: T+0-2d | F44: Bulk Mining | G44: Negative
A45: Africa Commodity Exporters Impact | B45: -1.8 | C45: % per point | D45: MEDIUM | E45: T+2-7d | F45: Africa EM | G45: Negative
...

Sheet 07 — Market Drivers
A1: MARKET DRIVERS & KEY RISKS — All 45 Emerging Markets
A2: Region | B2: ID | C2: Country | D2: Driver 1 | E2: Driver 2 | F2: Driver 3 | G2: Driver 4 | H2: Key Risk
A3: South Asia | B3: IN | C3: 🇮🇳 India | D3: IT Exports | E3: FII Flows | F3: Oil Imports | G3: Monsoon | H3: Oil Price Shock
A4: South Asia | B4: PK | C4: 🇵🇰 Pakistan | D4: IMF Program | E4: Remittances | F4: China CPEC | G4: Agriculture | H4: IMF Bailout Risk
A5: South Asia | B5: BD | C5: 🇧🇩 Bangladesh | D5: Garment Exports | E5: Remittances | F5: China FDI | H5: Political Instability
A6: South Asia | B6: LK | C6: 🇱🇰 Sri Lanka | D6: Tourism | E6: Tea Exports | F6: IMF Recovery | H6: Debt Restructuring
A7: Southeast Asia | B7: ID | C7: 🇮🇩 Indonesia | D7: Coal Exports | E7: Palm Oil | F7: Nickel | G7: China Demand | H7: Coal Demand Collapse
A8: Southeast Asia | B8: MY | C8: 🇲🇾 Malaysia | D8: Palm Oil | E8: Semiconductor | F8: LNG Exports | G8: Tourism | H8: USD Strength
A9: Southeast Asia | B9: TH | C9: 🇹🇭 Thailand | D9: Tourism | E9: Auto Exports | F9: Electronics | G9: Agriculture | H9: Political Instability
A10: Southeast Asia | B10: PH | C10: 🇵🇭 Philippines | D10: Remittances | E10: BPO Services | F10: Real Estate | G10: Consumption | H10: Oil Imports
A11: Southeast Asia | B11: VN | C11: 🇻🇳 Vietnam | D11: Manufacturing | E11: Electronics Exports | F11: FDI Inflows | G11: Tourism | H11: China Slowdown
A12: Southeast Asia | B12: SG | C12: 🇸🇬 Singapore | D12: Trade Hub | E12: REIT Yields | F12: Finance | G12: Tech | H12: Global Trade Slowdown
A13: East Asia | B13: CN | C13: 🇨🇳 China | D13: Manufacturing PMI | E13: Property Sector | F13: Credit Impulse | G13: Exports | H13: Property Crisis
A14: East Asia | B14: KR | C14: 🇰🇷 South Korea | D14: Semiconductor | E14: K-Pop/Tech | F14: China Exports | G14: Auto | H14: China Slowdown
A15: East Asia | B15: TW | C15: 🇹🇼 Taiwan | D15: TSMC/Semiconductors | E15: USD Earnings | F15: AI Demand | H15: Geopolitical Risk
A16: East Asia | B16: HK | C16: 🇭🇰 Hong Kong | D16: China Proxy | E16: Finance Hub | F16: Real Estate | G16: USD Peg | H16: China Regulatory
A17: Latin America | B17: BR | C17: 🇧🇷 Brazil | D17: Iron Ore | E17: Soybean | F17: Oil (Petrobras) | G17: Commodities | H17: Political Risk
A18: Latin America | B18: MX | C18: 🇲🇽 Mexico | D18: US Trade (USMCA) | E18: Remittances | F18: Oil | G18: Nearshoring | H18: US Policy Risk
A19: Latin America | B19: CL | C19: 🇨🇱 Chile | D19: Copper | E19: Lithium | F19: Agriculture | H19: Copper Price
A20: Latin America | B20: CO | C20: 🇨🇴 Colombia | D20: Oil Exports | E20: Coal | F20: Agriculture | G20: Remittances | H20: Oil Price Fall
A21: Latin America | B21: PE | C21: 🇵🇪 Peru | D21: Copper | E21: Gold | F21: Silver | G21: Zinc | H21: Political Instability
A22: Latin America | B22: AR | C22: 🇦🇷 Argentina | D22: IMF Program | E22: Soybean | F22: Lithium | G22: Milei Reforms | H22: Hyperinflation
A23: EMEA — Africa | B23: ZA | C23: 🇿🇦 South Africa | D23: Gold | E23: Platinum | F23: Coal | G23: China Demand | H23: Power Crisis (Eskom)
A24: EMEA — Africa | B24: NG | C24: 🇳🇬 Nigeria | D24: Oil (NNPC) | E24: Agriculture | F24: Diaspora Remittances | H24: FX Volatility
A25: EMEA — Africa | B25: EG | C25: 🇪🇬 Egypt | D25: Suez Canal | E25: Tourism | F25: Gas Exports | G25: IMF Program | H25: Currency Devaluation
A26: EMEA — Africa | B26: KE | C26: 🇰🇪 Kenya | D26: Tea | E26: Coffee | F26: Fintech (M-Pesa) | G26: Horticulture | H26: USD Debt Burden
A27: EMEA — Africa | B27: GH | C27: 🇬🇭 Ghana | D27: Gold | E27: Cocoa | F27: Oil (Offshore) | G27: IMF Recovery | H27: Debt Restructuring
A28: EMEA — Africa | B28: MA | C28: 🇲🇦 Morocco | D28: Phosphates | E28: Tourism | F28: Auto Exports | G28: Remittances | H28: Europe Slowdown
A29: EMEA — Africa | B29: TZ | C29: 🇹🇿 Tanzania | D29: Gold | E29: Tourism (Serengeti) | F29: Agriculture | G29: Gas (LNG) | H29: Infrastructure Gap
A30: Middle East | B30: SA | C30: 🇸🇦 Saudi Arabia | D30: Oil (OPEC+) | E30: Vision 2030 | F30: NEOM | G30: Aramco | H30: Oil Price Fall
A31: Middle East | B31: AE | C31: 🇦🇪 UAE | D31: Oil | E31: Tourism | F31: Finance Hub | G31: Real Estate | H31: Oil Dependency
A32: Middle East | B32: QA | C32: 🇶🇦 Qatar | D32: LNG Exports | E32: Finance | F32: FIFA Legacy | G32: Sovereign Fund | H32: LNG Price Volatility
A33: Middle East | B33: TR | C33: 🇹🇷 Turkey | D33: Manufacturing | E33: Tourism | F33: Remittances | G33: Defense | H33: Lira Depreciation
A34: Middle East | B34: IL | C34: 🇮🇱 Israel | D34: Tech/Cybersecurity | E34: Pharma | F34: Tourism | G34: Defense | H34: Geopolitical Risk
A35: Middle East | B35: KW | C35: 🇰🇼 Kuwait | D35: Oil (KPC) | E35: Sovereign Fund | F35: Finance | G35: Real Estate | H35: Oil Dependency
A36: Emerging Europe | B36: PL | C36: 🇵🇱 Poland | D36: EU Funds | E36: Manufacturing | F36: Banking | G36: Energy Transition | H36: Russia Proximity
A37: Emerging Europe | B37: CZ | C37: 🇨🇿 Czech Rep. | D37: Auto Manufacturing | E37: EU Trade | F37: Finance | H37: Germany Recession
A38: Emerging Europe | B38: HU | C38: 🇭🇺 Hungary | D38: Auto/Manufacturing | E38: EU Funds | F38: Banking | G38: Tourism | H38: Energy Costs
A39: Emerging Europe | B39: RO | C39: 🇷🇴 Romania | D39: IT Services | E39: Auto | F39: Agriculture | G39: EU Funds | H39: Large Deficit
A40: Emerging Europe | B40: GR | C40: 🇬🇷 Greece | D40: Tourism | E40: Shipping | F40: Agriculture | G40: Real Estate | H40: Debt Level

Sheet 08 — Pricing Tiers
A1: PLATFORM PRICING TIERS & REVENUE MODEL
A2: Tier | B2: Price ($/Month) | C2: Target Users | D2: Year 2 Users | E2: MRR ($) | F2: ARR ($) | G2: Data Delay | H2: Key Features | I2: Primary Persona | J2: Gross Margin %
A3: Explorer | B3: 0 | C3: 50000 | D3: 50000 | E3: =B3*D3 -> 0 | F3: =E3*12 -> 0 | G3: 15 min delay | H3: Portfolio tracking, basic correlation, market snapshot | I3: Retail — Top funnel | J3: 0
A4: Investor | B4: 29 | C4: 50000 | D4: 50000 | E4: =B4*D4 -> 1450000 | F4: =E4*12 -> 17400000 | G4: Real-time | H4: Full correlation matrix, AI insights, crisis alerts, all 45 EMs | I4: Retail — Paid | J4: 0.9
A5: Trader | B5: 99 | C5: 5000 | D5: 5000 | E5: =B5*D5 -> 495000 | F5: =E5*12 -> 5940000 | G5: Real-time | H5: Advanced charting, backtesting, lead-lag engine, API access | I5: Active Traders | J5: 0.89
A6: Professional | B6: 499 | C6: 500 | D6: 500 | E6: =B6*D6 -> 249500 | F6: =E6*12 -> 2994000 | G6: Real-time | H6: Alt data, custom models, white-label, PMS tools | I6: Family Office / PMS | J6: 0.87
A7: Enterprise | B7: 5000-50000 | C7: 50 | D7: 50 | E7: =25000*D7 -> 1250000 | F7: =E7*12 -> 15000000 | G7: Real-time+ | H7: Dedicated infra, on-premise, 24/7 support, custom integrations | I7: Institutional | J7: 0.85
A9: YEAR 2 TOTALS | E9: =SUM(E3:E7) -> 3444500 | F9: =SUM(F3:F7) -> 41334000

Sheet 09 — Scenario Analysis
A1: SCENARIO ANALYSIS — Portfolio Impact Models
A2: Scenario | B2: Input Parameter | C2: Portfolio AUM ($M) | D2: Expected Impact ($M) | E2: Impact (%) | F2: Confidence | G2: Timeline | H2: Key Sectors Affected
A3: FED HIKE 50bps | B3: Rate change: +0.50% | C3: 847 | D3: =-0.0099*C3 -> -8.3853 | E3: =D3/C3 -> -0.0099 | F3: 0.76 | G3: T+2-5 days | H3: Banks(-1.2%), Auto(-0.8%), IT(+0.5-1.2%), OMCs(-0.3%)
A4: FED HIKE 25bps | B4: Rate change: +0.25% | C4: 847 | D4: =-0.005*C4 -> -4.235 | E4: =D4/C4 -> -0.005 | F4: 0.76 | G4: T+2-5 days | H4: Banks(-0.6%), Auto(-0.4%), IT(+0.3-0.6%)
A5: OIL SURGE $10 | B5: Brent: $87→$97 | C5: 847 | D5: =-0.0143*C5 -> -12.1121 | E5: =D5/C5 -> -0.0143 | F5: 0.74 | G5: T+0-30 days | H5: OMCs(-1.2%), Airlines(-0.8%), IT(+0.5%), Logistics(-0.5%)
A6: OIL SPIKE $100 | B6: Brent: $87→$100 | C6: 847 | D6: =-0.0192*C6 -> -16.2624 | E6: =D6/C6 -> -0.0192 | F6: 0.74 | G6: T+0-30 days | H6: OMCs(-2%), Airlines(-1.5%), Pharma(+0.8%), IT(+1%)
A7: CHINA STIMULUS | B7: PMI: 49→53 | C7: 847 | D7: =0.0179*C7 -> 15.1613 | E7: =D7/C7 -> 0.0179 | F7: 0.68 | G7: T+3-10 days | H7: Metals(+6%), Cement(+3%), Infra(+4%), Mining(+8%)
A8: CHINA SLOWDOWN | B8: PMI: 49→46 | C8: 847 | D8: =-0.012*C8 -> -10.164 | E8: =D8/C8 -> -0.012 | F8: 0.68 | G8: T+1-7 days | H8: Tata Steel(-4%), Hindalco(-3%), Vedanta(-3%)
A9: USD DOLLAR +5% | B9: DXY: 104→109 | C9: 847 | D9: =-0.018*C9 -> -15.246 | E9: =D9/C9 -> -0.018 | F9: 0.71 | G9: T+0-7 days | H9: All EM FX, FII outflows, IT(+2.5%), Pharma(+1.5%)
A10: EM CRISIS EVENT | B10: VIX spike > 35 | C10: 847 | D10: =-0.12*C10 -> -101.64 | E10: =D10/C10 -> -0.12 | F10: 0.73 | G10: T+0-14 days | H10: All EM equities, correlation spike to 0.85+
A11: INDIA RATE CUT | B11: RBI -25bps | C11: 847 | D11: =0.008*C11 -> 6.776 | E11: =D11/C11 -> 0.008 | F11: 0.72 | G11: T+0-5 days | H11: Banks(+1.5%), NBFC(+2%), Real Estate(+2%)
A12: GLOBAL RECESSION | B12: SPX -20% | C12: 847 | D12: =-0.14*C12 -> -118.58 | E12: =D12/C12 -> -0.14 | F12: 0.65 | G12: T+0-30 days | H12: All assets, 30-40% drawdown, gold safe haven

Sheet 10 — Summary Dashboard
A1: ALPHAEDGE — CROSS-SHEET KPI SUMMARY
A2: ── MARKET COVERAGE | C2: Notes / Source
A3: Total Emerging Markets Tracked | B3: ='01 — Market Parameters'!A2 -> Region | D3: Count of all markets in the engine
A4: Market Coverage Formula | B4: =COUNTA('01 — Market Parameters'!C3:C47) -> 38 | D4: Auto-count from sheet 01
A5: Regions Covered | B5: 7 | D5: South Asia, SE Asia, East Asia, LatAm, Africa, ME, E.Europe
A6: Frontier Markets | B6: =COUNTIF('01 — Market Parameters'!J3:J47,"Frontier") -> 10 | D6: Auto from sheet 01
A7: Emerging Markets | B7: =COUNTIF('01 — Market Parameters'!J3:J47,"Emerging") -> 22 | D7: Auto from sheet 01
A8: ── CORRELATION STATISTICS
A9: Avg SPX Correlation (all EMs) | B9: =AVERAGE('02 — Correlation Matrix'!D3:D47) -> 0.47052632 | D9: DCC-GARCH 30-day rolling
A10: Max SPX Correlation | B10: =MAX('02 — Correlation Matrix'!D3:D47) -> 0.76 | D10: Highest market corr to SPX
A11: Markets High Corr to SPX (>0.6) | B11: =COUNTIF('02 — Correlation Matrix'!D3:D47,">0.6") -> 8 | D11: Markets that follow SPX closely
A12: Markets Oil-Positive (corr>0.5) | B12: =COUNTIF('02 — Correlation Matrix'!E3:E47,">0.5") -> 7 | D12: Net oil exporters by correlation
A13: Markets China-Linked (corr>0.5) | B13: =COUNTIF('02 — Correlation Matrix'!H3:H47,">0.5") -> 11 | D13: Commodity demand dependent
A14: ── RISK STATISTICS
A15: Avg Risk Score (all EMs) | B15: =AVERAGE('03 — Risk & Macro Scores'!D3:D47) -> 49.684211 | D15: 0=lowest, 100=highest risk
A16: Markets: Critical Risk (score>70) | B16: =COUNTIF('03 — Risk & Macro Scores'!D3:D47,">70") -> 6 | D16: Highest vulnerability
A17: Markets: High Inflation (CPI>15%) | B17: =COUNTIF('03 — Risk & Macro Scores'!G3:G47,">0.15") -> 6 | D17: Crisis inflation threshold
A18: Avg GDP Growth (all EMs) | B18: =AVERAGE('03 — Risk & Macro Scores'!F3:F47) -> 0.028052632 | D18: Growth weighted average
A19: Markets Growing >5% GDP | B19: =COUNTIF('03 — Risk & Macro Scores'!F3:F47,">0.05") -> 5 | D19: High-growth emerging markets
A20: ── CRISIS PREDICTOR
A21: Current Crisis Probability | B21: ='04 — Crisis Predictor'!B11 -> 0.225 | D21: From crisis predictor model
A22: Active Signals (of 5 total) | B22: =COUNTIF('04 — Crisis Predictor'!G5:G9,"ACTIVE") -> 3 | D22: Signals currently triggered
A23: Total Signal Weight Activated | B23: ='04 — Crisis Predictor'!B11 -> 0.225 | D23: Weighted sum of active signals
A24: ── PLATFORM REVENUE MODEL
A25: Year 2 Target MRR ($) | B25: ='08 — Pricing Tiers'!E9 -> 3444500 | D25: From pricing model
A26: Year 2 Target ARR ($) | B26: ='08 — Pricing Tiers'!F9 -> 41334000 | D26: Annual Recurring Revenue
A27: Gross Margin (avg across tiers) | B27: 0.89 | D27: 89% gross margin target
A28: CAC (Customer Acquisition Cost) | B28: 45 | D28: $45 blended across channels
A29: LTV (Customer Lifetime Value) | B29: 194 | D29: $194 based on 6.7 month avg life
A30: LTV / CAC Ratio | B30: 45 | D30: >3x is healthy; target 4.3x
B31: =B29/B30 -> 4.3111111
